<?xml version="1.0" ?>
<robot name="assemble">


<link name="base_link">
  <inertial>
    <origin rpy="0 0 0" xyz="0.1525 0.1525 0.008157"/>
    <mass value="9.339688"/>
    <inertia ixx="0.085521" ixy="0.0" ixz="-0.0" iyy="0.085521" iyz="-0.0" izz="0.165754"/>
  </inertial>
  <visual>
    <origin rpy="0 0 0" xyz="0 0 0"/>
    <geometry>
      <mesh filename="package://fusion2urdf/assemble/bin_stl/base_link_m-binary.stl"/>
    </geometry>
    <material name="red">
      <color rgba="1 0 0 2"/>
    </material>
  </visual>
  <collision>
    <origin rpy="0 0 0" xyz="0 0 0"/>
    <geometry>
      <mesh filename="package://fusion2urdf/assemble/bin_stl/base_link_m-binary.stl"/>
    </geometry>
  </collision>
</link>



<link name="kudou_v2_3">
  <inertial>
    <origin rpy="0 0 0" xyz="0.0029860000000000164 -0.0009409999999999974 0.015137000000000001"/>
    <mass value="3.008445"/>
    <inertia ixx="0.006087" ixy="0.000274" ixz="0.00048" iyy="0.006842" iyz="-0.000759" izz="0.004517"/>
  </inertial>
  <visual>
    <origin rpy="0 0 0" xyz="-0.24 -0.24 -0.013738"/>
    <geometry>
      <mesh filename="package://fusion2urdf/assemble/bin_stl/kudou_v2_3_m-binary.stl"/>
    </geometry>
    <material name="yellow">
      <color rgba="1 1 0 2"/>
    </material>
  </visual>
  <collision>
    <origin rpy="0 0 0" xyz="-0.24 -0.24 -0.013738"/>
    <geometry>
      <mesh filename="package://fusion2urdf/assemble/bin_stl/kudou_v2_3_m-binary.stl"/>
    </geometry>
  </collision>
</link>


<link name="tire_v2_1">
  <inertial>
    <origin rpy="0 0 0" xyz="0.016202999999999995 -0.0052269999999999955 -1.9999999999999944e-06"/>
    <mass value="0.736526"/>
    <inertia ixx="0.000346" ixy="-3.5e-05" ixz="-3.4e-05" iyy="0.000249" iyz="3.4e-05" izz="0.000238"/>
  </inertial>
  <visual>
    <origin rpy="0 0 0" xyz="-0.223808 -0.070286 0.000262"/>
    <geometry>
      <mesh filename="package://fusion2urdf/assemble/bin_stl/tire_v2_1_m-binary.stl"/>
    </geometry>
    <material name="silver">
      <color rgba="0 0 1 2"/>
    </material>
  </visual>
  <collision>
    <origin rpy="0 0 0" xyz="-0.223808 -0.070286 0.000262"/>
    <geometry>
      <mesh filename="package://fusion2urdf/assemble/bin_stl/tire_v2_1_m-binary.stl"/>
    </geometry>
  </collision>
</link>


<link name="tire_v2__3__1">
  <inertial>
    <origin rpy="0 0 0" xyz="0.016202999999999995 -0.005227000000000009 -1.9999999999999944e-06"/>
    <mass value="0.736526"/>
    <inertia ixx="0.000346" ixy="-3.5e-05" ixz="0.0" iyy="0.000249" iyz="0.0" izz="0.000238"/>
  </inertial>
  <visual>
    <origin rpy="0 0 0" xyz="-0.223808 -0.245286 0.000262"/>
    <geometry>
      <mesh filename="package://fusion2urdf/assemble/bin_stl/tire_v2__3__1_m-binary.stl"/>
    </geometry>
    <material name="silver">
      <color rgba="0 0 1 2"/>
    </material>
  </visual>
  <collision>
    <origin rpy="0 0 0" xyz="-0.223808 -0.245286 0.000262"/>
    <geometry>
      <mesh filename="package://fusion2urdf/assemble/bin_stl/tire_v2__3__1_m-binary.stl"/>
    </geometry>
  </collision>
</link>


<link name="tire_v2__2__1">
  <inertial>
    <origin rpy="0 0 0" xyz="0.016203000000000002 -0.005227000000000009 -1.9999999999999944e-06"/>
    <mass value="0.736526"/>
    <inertia ixx="0.000346" ixy="-3.5e-05" ixz="3.4e-05" iyy="0.000249" iyz="-3.4e-05" izz="0.000238"/>
  </inertial>
  <visual>
    <origin rpy="0 0 0" xyz="-0.048808 -0.245286 0.000262"/>
    <geometry>
      <mesh filename="package://fusion2urdf/assemble/bin_stl/tire_v2__2__1_m-binary.stl"/>
    </geometry>
    <material name="silver">
      <color rgba="0 0 1 2"/>
    </material>
  </visual>
  <collision>
    <origin rpy="0 0 0" xyz="-0.048808 -0.245286 0.000262"/>
    <geometry>
      <mesh filename="package://fusion2urdf/assemble/bin_stl/tire_v2__2__1_m-binary.stl"/>
    </geometry>
  </collision>
</link>



<link name="tire_v2__1__1">
  <inertial>
    <origin rpy="0 0 0" xyz="0.016203000000000002 -0.0052269999999999955 -1.9999999999999944e-06"/>
    <mass value="0.736526"/>
    <inertia ixx="0.000346" ixy="-3.5e-05" ixz="0.0" iyy="0.000249" iyz="-0.0" izz="0.000238"/>
  </inertial>
  <visual>
    <origin rpy="0 0 0" xyz="-0.048808 -0.070286 0.000262"/>
    <geometry>
      <mesh filename="package://fusion2urdf/assemble/bin_stl/tire_v2__1__1_m-binary.stl"/>
    </geometry>
    <material name="silver">
      <color rgba="0 0 1 2"/>
    </material>
  </visual>
  <collision>
    <origin rpy="0 0 0" xyz="-0.048808 -0.070286 0.000262"/>
    <geometry>
      <mesh filename="package://fusion2urdf/assemble/bin_stl/tire_v2__1__1_m-binary.stl"/>
    </geometry>
  </collision>
</link>


<link name="kudou_v2_4">
  <inertial>
    <origin rpy="0 0 0" xyz="0.0029860000000000025 -0.0009409999999999974 0.015137000000000001"/>
    <mass value="3.008445"/>
    <inertia ixx="0.006087" ixy="0.000274" ixz="-0.014722" iyy="0.006842" iyz="0.014443" izz="0.004517"/>
  </inertial>
  <visual>
    <origin rpy="0 0 0" xyz="-0.065 -0.24 -0.013738"/>
    <geometry>
      <mesh filename="package://fusion2urdf/assemble/bin_stl/kudou_v2_4_m-binary.stl"/>
    </geometry>
    <material name="yellow">
      <color rgba="0 1 0 2"/>
    </material>
  </visual>
  <collision>
    <origin rpy="0 0 0" xyz="-0.065 -0.24 -0.013738"/>
    <geometry>
      <mesh filename="package://fusion2urdf/assemble/bin_stl/kudou_v2_4_m-binary.stl"/>
    </geometry>
  </collision>
</link>



<link name="kudou_v2_2">
  <inertial>
    <origin rpy="0 0 0" xyz="0.0029860000000000164 -0.0009409999999999974 0.015137000000000001"/>
    <mass value="3.008445"/>
    <inertia ixx="0.006087" ixy="0.000274" ixz="0.015682" iyy="0.006842" iyz="-0.015961" izz="0.004517"/>
  </inertial>
  <visual>
    <origin rpy="0 0 0" xyz="-0.24 -0.065 -0.013738"/>
    <geometry>
      <mesh filename="package://fusion2urdf/assemble/bin_stl/kudou_v2_2_m-binary.stl"/>
    </geometry>
    <material name="yellow">
      <color rgba="0 1 0 2"/>
    </material>
  </visual>
  <collision>
    <origin rpy="0 0 0" xyz="-0.24 -0.065 -0.013738"/>
    <geometry>
      <mesh filename="package://fusion2urdf/assemble/bin_stl/kudou_v2_2_m-binary.stl"/>
    </geometry>
  </collision>
</link>



<link name="kudou_v2_1">
  <inertial>
    <origin rpy="0 0 0" xyz="0.0029860000000000025 -0.0009409999999999974 0.015137000000000001"/>
    <mass value="3.008445"/>
    <inertia ixx="0.006087" ixy="0.000274" ixz="0.00048" iyy="0.006842" iyz="-0.000759" izz="0.004516"/>
  </inertial>
  <visual>
    <origin rpy="0 0 0" xyz="-0.065 -0.065 -0.013738"/>
    <geometry>
      <mesh filename="package://fusion2urdf/assemble/bin_stl/kudou_v2_1_m-binary.stl"/>
    </geometry>
    <material name="yellow">
      <color rgba="0 1 0 2"/>
    </material>
  </visual>
  <collision>
    <origin rpy="0 0 0" xyz="-0.065 -0.065 -0.013738"/>
    <geometry>
      <mesh filename="package://fusion2urdf/assemble/bin_stl/kudou_v2_1_m-binary.stl"/>
    </geometry>
  </collision>
</link>



<joint name="yaw3" type="continuous">
  <origin rpy="0 0 0" xyz="0.24 0.24 0.013738"/>
  <parent link="base_link"/>
  <child link="kudou_v2_3"/>
  <axis xyz="-0.0 0.0 0.01"/>
</joint>

<transmission name="yaw3_tran">
  <type>transmission_interface/SimpleTransmission</type>
  <joint name="yaw3">
    <hardwareInterface>PositionJointInterface</hardwareInterface>
  </joint>
  <actuator name="yaw3_actr">
    <hardwareInterface>PositionJointInterface</hardwareInterface>
    <mechanicalReduction>100</mechanicalReduction>
  </actuator>
</transmission>


<joint name="kudou2" type="continuous">
  <origin rpy="0 0 0" xyz="-0.016192 0.005286 -0.014"/>
  <parent link="kudou_v2_2"/>
  <child link="tire_v2_1"/>
  <axis xyz="-0.009517 0.00307 -0.0"/>
</joint>
<transmission name="kudou2_tran">
  <type>transmission_interface/SimpleTransmission</type>
  <joint name="kudou2">
    <hardwareInterface>VelocityJointInterface</hardwareInterface>
  </joint>

  <actuator name="kudou2_actr">
    <hardwareInterface>VelocityJointInterface</hardwareInterface>
    <mechanicalReduction>100</mechanicalReduction>
  </actuator>
</transmission>


<joint name="kudou3" type="continuous">
  <origin rpy="0 0 0" xyz="-0.016192 0.005286 -0.014"/>
  <parent link="kudou_v2_3"/>
  <child link="tire_v2__3__1"/>
  <axis xyz="-0.009517 0.00307 -0.0"/>
</joint>

<transmission name="kudou3_tran">
  <type>transmission_interface/SimpleTransmission</type>
  <joint name="kudou3">
    <hardwareInterface>VelocityJointInterface</hardwareInterface>
  </joint>
  <actuator name="kudou3_actr">
    <hardwareInterface>VelocityJointInterface</hardwareInterface>
    <mechanicalReduction>100</mechanicalReduction>
  </actuator>
</transmission>



<joint name="kudou4" type="continuous">
  <origin rpy="0 0 0" xyz="-0.016192 0.005286 -0.014"/>
  <parent link="kudou_v2_4"/>
  <child link="tire_v2__2__1"/>
  <axis xyz="-0.009517 0.00307 -0.0"/>
</joint>
<transmission name="kudou4_tran">
  <type>transmission_interface/SimpleTransmission</type>
  <joint name="kudou4">
    <hardwareInterface>VelocityJointInterface</hardwareInterface>
  </joint>
  <actuator name="kudou4_actr">
    <hardwareInterface>VelocityJointInterface</hardwareInterface>
    <mechanicalReduction>100</mechanicalReduction>
  </actuator>
</transmission>


<joint name="kudou1" type="continuous">
  <origin rpy="0 0 0" xyz="-0.016192 0.005286 -0.014"/>
  <parent link="kudou_v2_1"/>
  <child link="tire_v2__1__1"/>
  <axis xyz="-0.009517 0.00307 -0.0"/>
</joint>
<transmission name="kudou1_tran">
  <type>transmission_interface/SimpleTransmission</type>
  <joint name="kudou1">
    <hardwareInterface>VelocityJointInterface</hardwareInterface>
  </joint>
  <actuator name="kudou1_actr">
    <hardwareInterface>VelocityJointInterface</hardwareInterface>

    <mechanicalReduction>100</mechanicalReduction>
  </actuator>
</transmission>


<joint name="yaw4" type="continuous">
  <origin rpy="0 0 0" xyz="0.065 0.24 0.013738"/>
  <parent link="base_link"/>
  <child link="kudou_v2_4"/>
  <axis xyz="-0.0 0.0 0.01"/>
</joint>
<transmission name="yaw4_tran">
  <type>transmission_interface/SimpleTransmission</type>
  <joint name="yaw4">
    <hardwareInterface>PositionJointInterface</hardwareInterface>
  </joint>
  <actuator name="yaw4_actr">
    <hardwareInterface>PositionJointInterface</hardwareInterface>
    <mechanicalReduction>100</mechanicalReduction>
  </actuator>
</transmission>


<joint name="yaw2" type="continuous">
  <origin rpy="0 0 0" xyz="0.24 0.065 0.013738"/>
  <parent link="base_link"/>
  <child link="kudou_v2_2"/>
  <axis xyz="-0.0 -0.0 0.01"/>
</joint>
<transmission name="yaw2_tran">
  <type>transmission_interface/SimpleTransmission</type>
  <joint name="yaw2">
    <hardwareInterface>PositionJointInterface</hardwareInterface>
  </joint>
  <actuator name="yaw2_actr">
    <hardwareInterface>PositionJointInterface</hardwareInterface>
    <mechanicalReduction>100</mechanicalReduction>
  </actuator>
</transmission>


<joint name="yaw1" type="continuous">
  <origin rpy="0 0 0" xyz="0.065 0.065 0.013738"/>
  <parent link="base_link"/>
  <child link="kudou_v2_1"/>
  <axis xyz="-0.0 -0.0 0.01"/>
</joint>
<transmission name="yaw1_tran">
  <type>transmission_interface/SimpleTransmission</type>
  <joint name="yaw1">
    <hardwareInterface>PositionJointInterface</hardwareInterface>
  </joint>
  <actuator name="yaw1_actr">
    <hardwareInterface>PositionJointInterface</hardwareInterface>
    <mechanicalReduction>100</mechanicalReduction>
  </actuator>
</transmission>

Hokuyo Laser 
  <link name="hokuyo_link1">
    <collision>
      <origin xyz="0 0 0" rpy="0 0 0"/>
      <geometry>
        <box size="0.1 0.1 0.1"/>
      </geometry>
    </collision>

    <visual>
      <origin xyz="0 0 0" rpy="0 0 0"/>
      <geometry>
        <mesh filename="package://rrbot_description/meshes/hokuyo.dae"/>
      </geometry>
    </visual>


  </link>
  <joint name="hokuyo_joint1" type="fixed">
    <axis xyz="0 1 0" />
    <origin xyz="0.15 0.3 0.07" rpy="0 0 1.5"/>
    <parent link="base_link"/>
    <child link="hokuyo_link1"/>
  </joint>



<gazebo>
  <plugin  name="gazebo_ros_control" filename="libgazebo_ros_control.so">
  <robotNamespace>assemble</robotNamespace>
  <legacyModeNS>true</legacyModeNS>
  </plugin>
</gazebo>

<gazebo reference="base_link">
  <selfCollide>true</selfCollide>
  <mu1 value="0.8"/><mu2 value="0.8"/>
</gazebo>

<gazebo reference="kudou_v2_3">
  <selfCollide>true</selfCollide>
  <mu1 value="0.8"/><mu2 value="0.8"/>
</gazebo>

<gazebo reference="kudou_v2_1">
  <selfCollide>true</selfCollide>
  <mu1 value="0.8"/><mu2 value="0.8"/>
</gazebo>

<gazebo reference="kudou_v2_4">
  <selfCollide>true</selfCollide>
  <mu1 value="0.8"/><mu2 value="0.8"/>
</gazebo>

<gazebo reference="kudou_v2_2">
  <selfCollide>true</selfCollide>
  <mu1 value="0.8"/><mu2 value="0.8"/>
</gazebo>




<gazebo reference="tire_v2__1__1">
  <selfCollide>true</selfCollide>
  <mu1 value="0.8"/><mu2 value="0.8"/>
</gazebo>

<gazebo reference="tire_v2__2__1">
  <selfCollide>true</selfCollide>
  <mu1 value="0.8"/><mu2 value="0.8"/>
</gazebo>

<gazebo reference="tire_v2__3__1">
  <selfCollide>true</selfCollide>
  <mu1 value="0.8"/><mu2 value="0.8"/>
</gazebo>

<gazebo reference="tire_v2_1">
  <selfCollide>true</selfCollide>
  <mu1 value="0.8"/><mu2 value="0.8"/>
</gazebo>

<!-- hokuyo-->
  <gazebo reference="hokuyo_link1">
    <sensor type="ray" name="head_hokuyo_sensor">
      <pose>0 0 0 0 0 0</pose>
      <visualize>false</visualize>
      <update_rate>40</update_rate>
      <ray>
        <scan>
          <horizontal>
            <samples>720</samples>
            <resolution>1</resolution>
            <min_angle>-1.570796</min_angle>
            <max_angle>1.570796</max_angle>
          </horizontal>
        </scan>
        <range>
          <min>0.10</min>
          <max>30.0</max>
          <resolution>0.01</resolution>
        </range>
        <noise>
          <type>gaussian</type>
          <!--Noise parameters based on published spec for Hokuyo laser
               achieving "+-30mm" accuracy at range < 10m.  A mean of 0.0m and
               stddev of 0.01m will put 99.7% of samples within 0.03m of the true
               reading. -->
          <mean>0.0</mean>
          <stddev>0.01</stddev>
        </noise>
      </ray>
      <plugin name="gazebo_ros_head_hokuyo_controller" filename="libgazebo_ros_laser.so">
        <topicName>/scan</topicName>
        <frameName>hokuyo_link1</frameName>
      </plugin>
    </sensor>
  </gazebo>


</robot>
