<?xml version="1.0"?>
<robot name="1gou">

	<link name="base_link">
		<visual>
			<geometry>
				<box size="0.2 0.3 0.1"/>
				<origin rpy="0 0 1.54" xyz="0 0 0.05"/>
				<material name="white">
					<color rgba="0.5 0.5 0.5 1"/>
				</material>
			</geometry>

		</visual>
		<collision>
			<geometry>
				<box size="0.2 0.3 0.1"/>
			</geometry>

		</collision>
		<inertial>
     		 <origin xyz="0 0 0"/>
		<mass value="0.500"/>
      		<inertia ixx="0.0020833333" ixy="0" ixz="0" iyy="0.0041666666" iyz="0" izz="0.0054166666"/>
    		</inertial>

	</link>


	<link name="wheel1">
		<visual>
			<geometry>
				<cylinder length="0.09" radius="0.09"/>
				
			</geometry>
			<origin rpy="0 0 0" xyz="0 0 0"/>
			<material name="black">
				<color rgba="0.1 0.1 0.1 1"/>
			</material>

		</visual>
		<collision>
			<geometry>
				<cylinder length="0.09" radius="0.09"/>
			</geometry>

		</collision>
		
		<inertial>
      			<origin xyz="0 0 0"/>
     			 <mass value="0.500"/>
      			<inertia ixx="0.00135" ixy="0" ixz="0" iyy="0.001354" iyz="0" izz="0.002025"/>
    		</inertial>

	</link>

	<joint name="base_to_wheel1" type="continuous">
	
		<parent link="base_link"/>
		<child link="wheel1"/>
		<origin rpy="0 1.5707 0" xyz="0.145 0.15 0"/>
		<axis xyz="0 0 1"/>
	</joint>

	<link name="wheel2">
		<visual>
			<geometry>
				<cylinder length="0.09" radius="0.09"/>
				
			</geometry>
			<origin rpy="0 0 0" xyz="0 0 0"/>
			<material name="black">
				<color rgba="0.1 0.1 0.1 1"/>
			</material>

		</visual>
		<collision>
			<geometry>
				<cylinder length="0.09" radius="0.09"/>
			</geometry>

		</collision>
		<inertial>
      			<origin xyz="0 0 0"/>
     			 <mass value="0.500"/>
      			<inertia ixx="0.00135" ixy="0" ixz="0" iyy="0.001354" iyz="0" izz="0.002025"/>
    		</inertial>

	</link>

	<joint name="base_to_wheel2" type="continuous">
	
		<parent link="base_link"/>
		<child link="wheel2"/>
		<origin rpy="0 1.5707 0" xyz="-0.145 0.15 0"/>
		<axis xyz="0 0 1"/>
	</joint>

	<link name="wheel3">
		<visual>
			<geometry>
				<cylinder length="0.09" radius="0.09"/>
				
			</geometry>
			<origin rpy="0 0 0" xyz="0 0 0"/>
			<material name="black">
				<color rgba="0.1 0.1 0.1 1"/>
			</material>

		</visual>
		<collision>
			<geometry>
				<cylinder length="0.09" radius="0.09"/>
			</geometry>

		</collision>
		<inertial>
      			<origin xyz="0 0 0"/>
     			 <mass value="0.500"/>
      			<inertia ixx="0.00135" ixy="0" ixz="0" iyy="0.001354" iyz="0" izz="0.002025"/>
    		</inertial>

	</link>

	<joint name="base_to_wheel3" type="continuous">
	
		<parent link="base_link"/>
		<child link="wheel3"/>
		<origin rpy="0 1.5707 0" xyz="0.145 -0.15 0"/>
		<axis xyz="0 0 1"/>
	</joint>

	<link name="wheel4">
		<visual>
			<geometry>
				<cylinder length="0.09" radius="0.09"/>
				
			</geometry>
			<origin rpy="0 0 0" xyz="0 0 0"/>
			<material name="black">
				<color rgba="0.1 0.1 0.1 1"/>
			</material>

		</visual>
		<collision>
			<geometry>
				<cylinder length="0.09" radius="0.09"/>
			</geometry>

		</collision>

		<inertial>
      			<origin xyz="0 0 0"/>
     			 <mass value="0.500"/>
      			<inertia ixx="0.00135" ixy="0" ixz="0" iyy="0.001354" iyz="0" izz="0.002025"/>
    		</inertial>

	</link>

	<joint name="base_to_wheel4" type="continuous">
	
		<parent link="base_link"/>
		<child link="wheel4"/>
		<origin rpy="0 1.5707 0" xyz="-0.145 -0.15 0"/>
		<axis xyz="0 0 1"/>
	</joint>
	<link name="base_footprint"/>
  		<joint name="base_link_joint" type="fixed">
    		<parent link="base_footprint"/>
    		<child link="base_link"/>
    		<origin xyz="0 0 0.100"/>
  		</joint>

	<!-- ===============  Transmission =============== -->
  <transmission name="left_wheel4_trans">
    <type>transmission_interface/SimpleTransmission</type>
    <joint name="base_to_wheel4">
      <hardwareInterface>VelocityJointInterface</hardwareInterface>
    </joint>
    <actuator name="left_wheel4_motor">
      <hardwareInterface>VelocityJointInterface</hardwareInterface>
      <mechanicalReduction>30</mechanicalReduction>
    </actuator>
  </transmission>

   <transmission name="left_wheel3_trans">
    <type>transmission_interface/SimpleTransmission</type>
    <joint name="base_to_wheel3">
      <hardwareInterface>VelocityJointInterface</hardwareInterface>
    </joint>
    <actuator name="left_wheel3_motor">
      <hardwareInterface>VelocityJointInterface</hardwareInterface>
      <mechanicalReduction>30</mechanicalReduction>
    </actuator>
  </transmission>
  

  <transmission name="right_wheel1_trans">
    <type>transmission_interface/SimpleTransmission</type>
    <joint name="base_to_wheel1">
      <hardwareInterface>VelocityJointInterface</hardwareInterface>
    </joint>
    <actuator name="right_wheel1_motor">
      <hardwareInterface>VelocityJointInterface</hardwareInterface>
      <mechanicalReduction>30</mechanicalReduction>
    </actuator>
  </transmission>

  <transmission name="right_wheel2_trans">
    <type>transmission_interface/SimpleTransmission</type>
    <joint name="base_to_wheel2">
      <hardwareInterface>VelocityJointInterface</hardwareInterface>
    </joint>
    <actuator name="right_wheel2_motor">
      <hardwareInterface>VelocityJointInterface</hardwareInterface>
      <mechanicalReduction>30</mechanicalReduction>
    </actuator>
  </transmission>

<!-- =============== Gazebo =============== -->
  <gazebo>
    <plugin name="gazebo_ros_control" filename="libgazebo_ros_control.so">
      <robotNamespace>my_robo</robotNamespace>
    </plugin>
  </gazebo>
 
  <gazebo reference="base_link">
    <selfCollide>true</selfCollide>
    <mu1 value="0.05" />
    <mu2 value="0.05" />
  </gazebo>
 
  <gazebo reference="wheel1">
    <selfCollide>true</selfCollide>
    <mu1 value="0.8" />
    <mu2 value="0.8" />
  </gazebo>
 
  <gazebo reference="wheel2">
    <selfCollide>true</selfCollide>
    <mu1 value="0.8" />
    <mu2 value="0.8" />
  </gazebo>
  <gazebo reference="wheel3">
    <selfCollide>true</selfCollide>
    <mu1 value="0.8" />
    <mu2 value="0.8" />
  </gazebo>
 
  <gazebo reference="wheel4">
    <selfCollide>true</selfCollide>
    <mu1 value="0.8" />
    <mu2 value="0.8" />
  </gazebo>









</robot>
